using System;

namespace Exception_7
{
	class MainClass
	{
		public static void Main (string[] args)
		{
			try
			{
				TestClass.Method1();
			}
			catch (DivideByZeroException ex)
			{
				Console.WriteLine($"Catch в Main : {ex.Message}");
			}
			finally
			{
				Console.WriteLine("Блок finally в Main");
			}
			Console.WriteLine("Конец метода Main");
		}
	}

	class TestClass
	{
		public static void Method1()
		{
			try
			{
				Method2();
			}
			catch (IndexOutOfRangeException ex)
			{
				Console.WriteLine($"Catch в Method1 : {ex.Message}");
			}
			finally
			{
				Console.WriteLine("Блок finally в Method1");
			}
			Console.WriteLine("Конец метода Method1");
		}
		static void Method2()
		{
			try
			{
				int x = 8;
				int y = x / 0;
				Console.WriteLine (y);
			}
			finally
			{
				Console.WriteLine("Блок finally в Method2");
			}
			Console.WriteLine("Конец метода Method2");
		}
	}
}
